<mujoco model="dyros_tocabi">
    <compiler angle="radian" meshdir="../meshes/" />
    <size njmax="500" nconmax="100" />

    <default>

        <joint damping="4.0" frictionloss="1.0"/>

        <motor ctrllimited="true" ctrlrange="-300 300"/>

        <default class="viz">
            <geom contype="0" conaffinity="0" group="1" type="mesh" rgba=".6 .6 .7 1"/>
        </default>

        <default class="cls">
            <geom group="2" rgba="0.79216 0.81961 0.93333 0.5"/>
        </default>

        <default class="cls_f">
            <geom group="2" rgba="0.79216 0.81961 0.93333 0.1" friction="1 0.005 0.0001"/>
        </default>

        <default class="FTsensor">
            <site type="cylinder" size="0.005 0.005" group="4" rgba=".1 .1 .9 1"/>
        </default>


    </default>

    <option timestep='0.0005' iterations="100" tolerance="1e-11" solver="Newton" jacobian="dense" cone="elliptic" noslip_iterations="75" noslip_tolerance="1e-9"/>

    <visual>
        <quality shadowsize="2048" offsamples="16"/>
        <map stiffness="10" znear="0.05"/>
    </visual>

    <asset>

        <mesh name="Pelvis_link" file="Pelvis_link2.STL" scale="0.001 0.001 0.001"/>
        <mesh name="HipRoll_R_link" file="HipRoll_R_link.STL" />
        <mesh name="HipCenter_R_Link" file="HipCenter_R_Link.STL" />
        <mesh name="Thigh_R_Link" file="Thigh_R_Link.STL" />
        <mesh name="Knee_R_Link" file="Knee_R_Link.STL" />
        <mesh name="AnkleCenter_R_Link" file="AnkleCenter_R_Link.STL" />
        <mesh name="AnkleRoll_R_Link" file="AnkleRoll_R_Link.STL" />
        <mesh name="HipRoll_L_Link" file="HipRoll_L_Link.STL" />
        <mesh name="HipCenter_L_Link" file="HipCenter_L_Link.STL" />
        <mesh name="Thigh_L_Link" file="Thigh_L_Link.STL" />
        <mesh name="Knee_L_Link" file="Knee_L_Link.STL" />
        <mesh name="AnkleCenter_L_Link" file="AnkleCenter_L_Link.STL" />
        <mesh name="AnkleRoll_L_Link" file="AnkleRoll_L_Link.STL" />
        <mesh name="waist1" file="waistyaw.STL" scale="0.001 0.001 0.001"/>
        <mesh name="waist2" file="waist2.STL" />
        <mesh name="upperbody" file="upperbody.STL" />
        <mesh name="R_shoulder1" file="R_shoulder1.STL" />
        <mesh name="R_shoulder2" file="R_shoulder2.STL" />
        <mesh name="R_shoulder3" file="R_shoulder3.STL" />
        <mesh name="R_arm" file="R_arm.STL" />
        <mesh name="R_elbow" file="R_elbow.STL" />
        <mesh name="R_forearm" file="R_forearm.STL" />
        <mesh name="R_wrist1" file="R_wrist1.STL" />
        <mesh name="L_shoulder1" file="L_shoulder1.STL" />
        <mesh name="L_shoulder2" file="L_shoulder2.STL" />
        <mesh name="L_shoulder3" file="L_shoulder3.STL" />
        <mesh name="L_arm" file="L_arm.STL" />
        <mesh name="L_elbow" file="L_elbow.STL" />
        <mesh name="L_forearm" file="L_forearm.STL" />
        <mesh name="L_wrist1" file="L_wrist1.STL" />
        <mesh name="neck" file="neck.STL" />
        <mesh name="head" file="head.STL" />
        <mesh name="hand" file="wrist2joint.STL" scale="0.001 0.001 0.001"/>

        <!--texture type="skybox" builtin="gradient" width="128" height="128" rgb1="1 1 1" rgb2="0 0 0"/-->
        <texture type="skybox" builtin="gradient" width="128" height="128" rgb1="0.4 0.6 0.8" rgb2="0 0 0"/>
        <texture name="texgeom" type="cube" builtin="flat" mark="cross" width="128" height="128" rgb1="0.6 0.6 0.6" rgb2="0.6 0.6 0.6" markrgb="1 1 1"/>
        <texture name="texplane" type="2d" builtin="checker" rgb1=".4 .4 .4" rgb2=".6 .6 .6" width="512" height="512"/>
        <material name='geom' texture="texgeom" texuniform="true"/>
        <material name='MatPlane' reflectance='0.3' texture="texplane" texrepeat="1 1" texuniform="true"/>
        <material name='MatPlane2' reflectance='0.3' />
    </asset>

    <worldbody>
        <geom name="ground" type="plane" pos="0 0 0" size="10 10 .05" rgba="0.7 0.6 0.5 1" material="MatPlane2" group="3"/>
        <light directional="true" diffuse=".8 .8 .8" pos="0 0 10" dir="0 0 -10"/>
        <light directional="true" diffuse=".5 .5 .5" pos="10 0 0" dir="-10 0 0"/>


        <body name="base_link" pos="0 0 1" euler="0 0 3.1415">
            <joint name="virtual_joint" type="free" limited='false' frictionloss="0" damping="0" stiffness="0" armature="0"/>
            <inertial pos="-0.0099622 0 0.012618" quat="0.5 0.5 -0.5 0.5" mass="0.90054" diaginertia="0.010198 0.0094751 0.0022311" />
            <geom class="viz" rgba="0.20313 0.20313 0.20313 1" quat="0.5 0.5 0.5 0.5" mesh="Pelvis_link" />
            <geom size="0.045 0.044" pos="0 0 0.019" type="cylinder" class="cls" />
            <geom size="0.045 0.055" pos="0 0.1025 0.03" type="cylinder" class="cls" />
            <geom size="0.045 0.055" pos="0 -0.1025 0.03" type="cylinder" class="cls" />
            <geom size="0.12 0.1525 0.025" pos="-0.058 0 0" type="box" class="cls" />
            <geom size="0.05 0.13 0.05" pos="-0.1 0 0.03" type="box" group="1"/>
            <site name="Pelvis_IMU" type="cylinder" size="0.005 0.005" group="4" rgba=".1 .1 .9 1"/>


            <body name="R_HipRoll_Link" pos="0 -0.1025 -0.1225">
                <inertial pos="-0.06477 0 0.05149" quat="-4.55125e-06 0.706109 4.5641e-06 0.708103" mass="2.679" diaginertia="0.114073 0.114073 0.114073" />
                <joint name="R_HipRoll_Joint" pos="0 0 0" axis="0 0 1" limited="true" range="-3.14 3.14" />
                <geom class="viz" rgba="0.20313 0.20313 0.20313 1" mesh="HipRoll_R_link" />
                <geom size="0.045 0.04" pos="-0.1 0 0" quat="0.707107 0 0.707107 0" type="cylinder" rgba="0.79216 0.81961 0.93333 1" />
                <geom size="0.077 0.05 0.01" pos="-0.016 0 0.085" type="box" rgba="0.79216 0.81961 0.93333 1" />
                <geom size="0.006 0.036 0.0475" pos="0.055 0 0.0475" type="box" rgba="0.79216 0.81961 0.93333 1" />
                <geom size="0.006 0.036 0.0475" pos="-0.087 0 0.0475" type="box" rgba="0.79216 0.81961 0.93333 1" />
                <body name="R_HipCenter_Link" pos="0 0 0">
                    <inertial pos="-0.04801 -0.0022 2e-05" quat="0.999982 -0.00595644 4.6683e-06 -2.7807e-08" mass="2.67" diaginertia="0.124407 0.124407 0.124407" />
                    <joint name="R_HipCenter_Joint" pos="0 0 0" axis="1 0 0" limited="true" range="-3.14 3.14" />
                    <geom class="viz" rgba="0.20313 0.20313 0.20313 1" mesh="HipCenter_R_Link" />
                    <geom size="0.05225 0.03 0.0475" pos="-0.0045 0 0" type="box" rgba="0.79216 0.81961 0.93333 1" />
                    <body name="R_Thigh_Link" pos="0 0 0">
                        <inertial pos="-0.00042 -0.00032 -0.18904" quat="0.707068 0.00145661 -0.000977354 0.707144" mass="5.366" diaginertia="0.339107 0.339107 0.339107" />
                        <joint name="R_Thigh_Joint" pos="0 0 0" axis="0 1 0" limited="true" range="-3.14 3.14" />
                        <geom class="viz" rgba="0.85938 0.07813 0.23438 1" mesh="Thigh_R_Link" />
                        <geom size="0.049 0.038815" pos="0 0 -0.35" quat="0.707107 0.707107 0 0" type="cylinder" rgba="0.79216 0.81961 0.93333 1" />
                        <geom size="0.06 0.10875" pos="0 0 -0.1923" type="cylinder" rgba="0.79216 0.81961 0.93333 1" />
                        <body name="R_Knee_Link" pos="0 0 -0.35">
                            <inertial pos="0.00429 0.00214 -0.1428" quat="0.707067 0.00548297 0.00738884 0.707087" mass="3.883" diaginertia="0.23895 0.23895 0.23895" />
                            <joint name="R_Knee_Joint" pos="0 0 0" axis="0 1 0" limited="true" range="-3.14 3.14" />
                            <geom class="viz" rgba="0.85938 0.07813 0.23438 1" mesh="Knee_R_Link" />
                            <geom size="0.06 0.1" pos="0 0 -0.175" type="cylinder" rgba="0.79216 0.81961 0.93333 1" />
                            <body name="R_AnkleCenter_Link" pos="0 0 -0.35">
                                <inertial pos="-0.00419 -0.0018 -0.0003" quat="0.498858 0.50114 0.501134 0.498863" mass="2.51" diaginertia="0.139901 0.139901 0.139901" />
                                <joint name="R_AnkleCenter_Joint" pos="0 0 0" axis="0 1 0" limited="true" range="-3.14 3.14" />
                                <geom class="viz" rgba="0.20313 0.20313 0.20313 1" mesh="AnkleCenter_R_Link" />
                                <geom size="0.05225 0.03 0.0475" pos="-0.0045 0 0" type="box" rgba="0.79216 0.81961 0.93333 1" />
                                <body name="R_AnkleRoll_Link" pos="0 0 0">
                                    <inertial pos="-0.00802 0 -0.08535" quat="0.999815 -0.000353889 0.0192239 9.30274e-05" mass="3.464" diaginertia="0.07616 0.07616 0.07616" />
                                    <joint name="R_AnkleRoll_Joint" pos="0 0 0" axis="1 0 0" limited="true" range="-3.14 3.14" />
                                    <geom class="viz" rgba="0.85938 0.07813 0.23438 1" mesh="AnkleRoll_R_Link" />
                                    <geom size="0.13 0.05 0.0135" pos="0.0317 0 -0.1233" type="box" rgba="0.79216 0.81961 0.93333 1" />
                                    <geom size="0.045 0.03125" pos="-0.08875 0 0" quat="0.707107 0 -0.707107 0" type="cylinder" rgba="0.79216 0.81961 0.93333 1" />
                                </body>
                            </body>
                        </body>
                    </body>
                </body>
            </body>
            <body name="L_HipRoll_Link" pos="0 0.1025 -0.1225">
                <inertial pos="-0.06477 0 0.05149" quat="-4.55125e-06 0.706109 4.5641e-06 0.708103" mass="2.679" diaginertia="0.114073 0.114073 0.114073" />
                <joint name="L_HipRoll_Joint" pos="0 0 0" axis="0 0 1" limited="true" range="-3.14 3.14" />
                <geom class="viz" rgba="0.20313 0.20313 0.20313 1" mesh="HipRoll_L_Link" />
                <geom size="0.045 0.04" pos="-0.1 0 0" quat="0.707107 0 0.707107 0" type="cylinder" rgba="0.79216 0.81961 0.93333 1" />
                <geom size="0.077 0.05 0.01" pos="-0.016 0 0.085" type="box" rgba="0.79216 0.81961 0.93333 1" />
                <geom size="0.006 0.036 0.0475" pos="0.055 0 0.0475" type="box" rgba="0.79216 0.81961 0.93333 1" />
                <geom size="0.006 0.036 0.0475" pos="-0.087 0 0.0475" type="box" rgba="0.79216 0.81961 0.93333 1" />
                <body name="L_HipCenter_Link" pos="0 0 0">
                    <inertial pos="-0.04801 0.0022 2e-05" quat="0.999982 -0.00595644 4.6683e-06 -2.7807e-08" mass="2.67" diaginertia="0.124407 0.124407 0.124407" />
                    <joint name="L_HipCenter_Joint" pos="0 0 0" axis="1 0 0" limited="true" range="-3.14 3.14" />
                    <geom class="viz" rgba="0.20313 0.20313 0.20313 1" mesh="HipCenter_L_Link" />
                    <geom size="0.05225 0.03 0.0475" pos="-0.0045 0 0" type="box" rgba="0.79216 0.81961 0.93333 1" />
                    <body name="L_Thigh_Link" pos="0 0 0">
                        <inertial pos="-0.00042 0.00032 -0.18904" quat="0.707068 0.00145661 -0.000977354 0.707144" mass="5.366" diaginertia="0.339107 0.339107 0.339107" />
                        <joint name="L_Thigh_Joint" pos="0 0 0" axis="0 1 0" limited="true" range="-3.14 3.14" />
                        <geom class="viz" rgba="0.85938 0.07813 0.23438 1" mesh="Thigh_L_Link" />
                        <geom size="0.049 0.038815" pos="0 0 -0.35" quat="0.707107 0.707107 0 0" type="cylinder" rgba="0.79216 0.81961 0.93333 1" />
                        <geom size="0.06 0.10875" pos="0 0 -0.1923" type="cylinder" rgba="0.79216 0.81961 0.93333 1" />
                        <body name="L_Knee_Link" pos="0 0 -0.35">
                            <inertial pos="0.00429 -0.00214 -0.1428" quat="0.707067 0.00548297 0.00738884 0.707087" mass="3.883" diaginertia="0.23895 0.23895 0.23895" />
                            <joint name="L_Knee_Joint" pos="0 0 0" axis="0 1 0" limited="true" range="-3.14 3.14" />
                            <geom class="viz" rgba="0.85938 0.07813 0.23438 1" mesh="Knee_L_Link" />
                            <geom size="0.06 0.1" pos="0 0 -0.175" type="cylinder" rgba="0.79216 0.81961 0.93333 1" />
                            <body name="L_AnkleCenter_Link" pos="0 0 -0.35">
                                <inertial pos="-0.00419 0.0018 -0.0003" quat="0.498858 0.50114 0.501134 0.498863" mass="2.51" diaginertia="0.139901 0.139901 0.139901" />
                                <joint name="L_AnkleCenter_Joint" pos="0 0 0" axis="0 1 0" limited="true" range="-3.14 3.14" />
                                <geom class="viz" rgba="0.20313 0.20313 0.20313 1" mesh="AnkleCenter_L_Link" />
                                <geom size="0.05225 0.03 0.0475" pos="-0.0045 0 0" type="box" rgba="0.79216 0.81961 0.93333 1" />
                                <body name="L_AnkleRoll_Link" pos="0 0 0">
                                    <inertial pos="-0.00802 0 -0.08535" quat="0.999815 -0.000353889 0.0192239 9.30274e-05" mass="3.464" diaginertia="0.07616 0.07616 0.07616" />
                                    <joint name="L_AnkleRoll_Joint" pos="0 0 0" axis="1 0 0" limited="true" range="-3.14 3.14" />
                                    <geom class="viz" rgba="0.85938 0.07813 0.23438 1" mesh="AnkleRoll_L_Link" />
                                    <geom size="0.13 0.05 0.0135" pos="0.0317 0 -0.1233" type="box" rgba="0.79216 0.81961 0.93333 1" />
                                    <geom size="0.045 0.03125" pos="-0.08875 0 0" quat="0.707107 0 -0.707107 0" type="cylinder" rgba="0.79216 0.81961 0.93333 1" />
                                </body>
                            </body>
                        </body>
                    </body>
                </body>
            </body>
            <body name="Waist1_Link" pos="0 0 0.18">
                <inertial pos="0 0 -0.04182" quat="0.707107 0.707107 0 0" mass="0.74235" diaginertia="0.00325468 0.00270188 0.00165546" />
                <joint name="Waist1_Joint" pos="0 0 0" axis="0 0 1" limited="true" range="-2.094 2.094" />
                <geom class="viz" rgba="0.85938 0.07813 0.23438 1" pos="0 0 -0.085" quat="0 0.707107 0 0.707107" mesh="waist1" />
                <geom size="0.05 0.01" pos="0 0 -0.096" type="cylinder" class="cls" />
                <geom size="0.047 0.065 0.005" pos="0 0 -0.081" type="box" class="cls" />
                <geom size="0.047 0.005 0.0455" pos="0 0.06 -0.0405" type="box" class="cls" />
                <geom size="0.047 0.005 0.0455" pos="0 -0.06 -0.0405" type="box" class="cls" />
                <body name="Waist2_Link" pos="0 0 0">
                    <inertial pos="-0.00065 0 1e-05" quat="0 0.707107 0 0.707107" mass="3.27104" diaginertia="0.00602216 0.0049746 0.00462286" />
                    <joint name="Waist2_Joint" pos="0 0 0" axis="0 1 0" limited="true" range="-2.094 2.094" />
                    <geom class="viz" rgba="0.20313 0.20313 0.20313 1" mesh="waist2" />
                    <geom size="0.055 0.05" quat="0.707107 0.707107 0 0" type="cylinder" class="cls" />
                    <geom size="0.05 0.05 0.03" pos="0.02 0 0" type="box" class="cls" />
                    <geom size="0.045 0.05 0.0455" pos="-0.02 0 0" type="box" class="cls" />
                    <body name="Upperbody_Link" pos="0 0 0">
                        <inertial pos="-0.04733 0 0.16266" quat="0.991857 0 -0.127356 0" mass="16.4339" diaginertia="0.274087 0.242243 0.173295" />
                        <joint name="Upperbody_Joint" pos="0 0 0" axis="-1 0 0" limited="true" range="-2.094 2.094" />
                        <geom class="viz" rgba="0.85938 0.07813 0.23438 1" mesh="upperbody" />
                        <geom size="0.105 0.11 0.05" pos="-0.03 0 0.2" type="box" class="cls" />
                        <geom size="0.105 0.055 0.035" pos="-0.03 0 0.115" type="box" class="cls" />
                        <geom size="0.06 0.035 0.07" pos="-0.08 0 0.32" type="box" class="cls" />
                        <geom size="0.054 0.045" pos="-0.115 0 0" quat="0.707107 0 0.707107 0" type="cylinder" class="cls" />
                        <geom size="0.04 0.035" pos="0.023 0.154 0.185" type="cylinder" class="cls" />
                        <geom size="0.04 0.035" pos="0.023 -0.154 0.185" type="cylinder" class="cls" />
                        <camera name="Head camera" euler="0 -1.5708 -1.5708" fovy="80" pos="0.084 0 0.647"/>
                        <body name="R_Shoulder1_Link" pos="0.023 -0.154 0.2275">
                            <inertial pos="-3e-05 -0.00397 0.06029" quat="0.678735 -0.0962618 0.0973029 0.721516" mass="1.6762" diaginertia="0.00195894 0.0019255 0.00165624" />
                            <joint name="R_Shoulder1_Joint" pos="0 0 0" axis="0 0 1" limited="true" range="-1.54 2.09" />
                            <geom class="viz" rgba="0.85938 0.07813 0.23438 1" mesh="R_shoulder1" />
                            <geom size="0.04 0.055" pos="0 0 0.05" type="cylinder" class="cls" />
                            <body name="R_Shoulder2_Link" pos="0 -0.0341 0.065">
                                <inertial pos="0.00107 -0.0491 -1e-05" quat="0.51724 0.479014 -0.520322 0.481948" mass="0.4016" diaginertia="0.00106758 0.000992068 0.000622085" />
                                <joint name="R_Shoulder2_Joint" pos="0 0 0" axis="0 -1 0" limited="true" range="-3.14159 3.14159" />
                                <geom class="viz" rgba="0.20313 0.20313 0.20313 1" mesh="R_shoulder2" />
                                <geom size="0.04 0.025" pos="0 -0.04 0" quat="0.707107 0.707107 0 0" type="cylinder" class="cls" />
                                <body name="R_Shoulder3_Link" pos="0 -0.115 0">
                                    <inertial pos="0.00262 -0.04826 0.00023" quat="0.708306 0.705235 0.0242641 0.0189048" mass="2.90141" diaginertia="0.00846389 0.00829694 0.00247136" />
                                    <joint name="R_Shoulder3_Joint" pos="0 0 0" axis="-1 0 0" limited="true" range="-1.9199 1.9199" />
                                    <geom class="viz" rgba="0.20313 0.20313 0.20313 1" mesh="R_shoulder3" />
                                    <geom size="0.04 0.06" pos="0 -0.06 0" quat="0.707107 0.707107 0 0" type="cylinder" class="cls" />
                                    <body name="R_Armlink_Link" pos="0 -0.1281 0">
                                        <inertial pos="0.01896 -0.11642 -0.0119" quat="0.503607 0.520285 -0.555379 0.408947" mass="0.43517" diaginertia="0.00318243 0.00291909 0.000624466" />
                                        <joint name="R_Armlink_Joint" pos="0 0 0" axis="0 -1 0" limited="true" range="-3.14159 3.14159" />
                                        <geom size="0.04 0.08" pos="0 -0.08 0" quat="0.707107 0.707107 0 0" type="cylinder" class="cls" />
                                        <geom class="viz" rgba="0.85938 0.07813 0.23438 1" mesh="R_arm" />
                                        <body name="R_Elbow_Link" pos="0 -0.207 -0.0325">
                                            <inertial pos="-0.00136 -0.05256 0.01764" quat="0.517663 0.708306 -0.39581 0.27141" mass="1.96511" diaginertia="0.0065354 0.00631431 0.00138011" />
                                            <joint name="R_Elbow_Joint" pos="0 0 0" axis="1 0 0" limited="true" range="-2.967 3.14159" />
                                            <geom size="0.04 0.04" pos="0 -0.08 0.0325" quat="0.707107 0.707107 0 0" type="cylinder" class="cls" />
                                            <geom size="0.04 0.04" quat="0.707107 0 0.707107 0" type="cylinder" class="cls" />
                                            <geom class="viz" rgba="0.20313 0.20313 0.20313 1" mesh="R_elbow" />
                                            <body name="R_Forearm_Link" pos="0 -0.1244 0.0325">
                                                <inertial pos="0.01426 -0.0767 0.00033" quat="0.55187 0.502809 -0.506596 0.431257" mass="0.30234" diaginertia="0.00126963 0.00106149 0.000388409" />
                                                <joint name="R_Forearm_Joint" pos="0 0 0" axis="0 -1 0" limited="true" range="-3.14159 3.14159" />
                                                <geom size="0.04 0.05" pos="0 -0.05 0" quat="0.707107 0.707107 0 0" type="cylinder" class="cls" />
                                                <geom size="0.025 0.04" pos="0 -0.1451 0" quat="0.707107 0 0.707107 0" type="cylinder" class="cls" />
                                                <geom class="viz" rgba="0.85938 0.07813 0.23438 1" mesh="R_forearm" />
                                                <body name="R_Wrist1_Link" pos="0 -0.1451 0">
                                                    <inertial pos="-0.00158 -0.02153 3e-05" quat="0.521107 0.474698 -0.525252 0.476676" mass="0.70923" diaginertia="0.00068319 0.000650504 0.000394066" />
                                                    <joint name="R_Wrist1_Joint" pos="0 0 0" axis="1 0 0" limited="true" range="-3.14159 3.14159" />
                                                    <geom size="0.02 0.03" pos="0 -0.046 0" type="cylinder" class="cls" />
                                                    <geom class="viz" rgba="0.20313 0.20313 0.20313 1" mesh="R_wrist1" />
                                                    <body name="R_Wrist2_Link" pos="0 -0.046 0">
                                                        <inertial pos="0.00063 -0.0536 0.00178" quat="0.707107 0.707107 0 0" mass="1" diaginertia="0.00086545 0.000820823 0.000696917" />
                                                        <joint name="R_Wrist2_Joint" pos="0 0 0" axis="0 0 1" limited="true" range="-2.094 2.094" />
                                                        <geom size="0.03 0.035 0.03" pos="0 -0.057 0" type="box" class="cls" />
                                                    </body>
                                                </body>
                                            </body>
                                        </body>
                                    </body>
                                </body>
                            </body>
                        </body>
                        <body name="L_Shoulder1_Link" pos="0.023 0.154 0.2275">
                            <inertial pos="-3e-05 0.00397 0.06029" quat="0.721516 0.0973029 -0.0962618 0.678735" mass="1.6762" diaginertia="0.00195894 0.0019255 0.00165624" />
                            <joint name="L_Shoulder1_Joint" pos="0 0 0" axis="0 0 1" limited="true" range="-2.09 1.54" />
                            <geom class="viz" rgba="0.85938 0.07813 0.23438 1" mesh="L_shoulder1" />
                            <geom size="0.04 0.055" pos="0 0 0.05" type="cylinder" class="cls" />
                            <body name="L_Shoulder2_Link" pos="0 0.0341 0.065">
                                <inertial pos="0.00107 0.0491 -1e-05" quat="0.479014 0.51724 -0.481948 0.520322" mass="0.4016" diaginertia="0.00106758 0.000992068 0.000622085" />
                                <joint name="L_Shoulder2_Joint" pos="0 0 0" axis="0 1 0" limited="true" range="-3.14159 3.14159" />
                                <geom class="viz" rgba="0.20313 0.20313 0.20313 1" mesh="L_shoulder2" />
                                <geom size="0.04 0.025" pos="0 0.04 0" quat="0.707107 0.707107 0 0" type="cylinder" class="cls" />
                                <body name="L_Shoulder3_Link" pos="0 0.115 0">
                                    <inertial pos="0.00262 0.04826 0.00023" quat="0.705235 0.708306 -0.0189048 -0.0242641" mass="2.90141" diaginertia="0.00846389 0.00829694 0.00247136" />
                                    <joint name="L_Shoulder3_Joint" pos="0 0 0" axis="-1 0 0" limited="true" range="-1.9199 1.9199" />
                                    <geom size="0.04 0.06" pos="0 0.06 0" quat="0.707107 0.707107 0 0" type="cylinder" class="cls" />
                                    <geom class="viz" rgba="0.20313 0.20313 0.20313 1" mesh="L_shoulder3" />
                                    <body name="L_Armlink_Link" pos="0 0.1281 0">
                                        <inertial pos="0.01896 0.11642 -0.0119" quat="0.520285 0.503607 -0.408947 0.555379" mass="0.43517" diaginertia="0.00318243 0.00291909 0.000624466" />
                                        <joint name="L_Armlink_Joint" pos="0 0 0" axis="0 1 0" limited="true" range="-3.14159 3.14159" />
                                        <geom size="0.04 0.08" pos="0 0.08 0" quat="0.707107 0.707107 0 0" type="cylinder" class="cls" />
                                        <geom class="viz" rgba="0.85938 0.07813 0.23438 1" mesh="L_arm" />
                                        <body name="L_Elbow_Link" pos="0 0.207 -0.0325">
                                            <inertial pos="-0.00136 0.05256 0.01764" quat="0.708306 0.517663 -0.27141 0.39581" mass="1.96511" diaginertia="0.0065354 0.00631431 0.00138011" />
                                            <joint name="L_Elbow_Joint" pos="0 0 0" axis="1 0 0" limited="true" range="-3.14159 2.8" />
                                            <geom size="0.04 0.04" pos="0 0.08 0.0325" quat="0.707107 0.707107 0 0" type="cylinder" class="cls" />
                                            <geom size="0.04 0.04" quat="0.707107 0 0.707107 0" type="cylinder" class="cls" />
                                            <geom class="viz" rgba="0.20313 0.20313 0.20313 1" mesh="L_elbow" />
                                            <body name="L_Forearm_Link" pos="0 0.1244 0.0325">
                                                <inertial pos="0.01426 0.0767 0.00033" quat="0.502809 0.55187 -0.431257 0.506596" mass="0.30234" diaginertia="0.00126963 0.00106149 0.000388409" />
                                                <joint name="L_Forearm_Joint" pos="0 0 0" axis="0 1 0" limited="true" range="-3.14159 3.14159" />
                                                <geom class="viz" rgba="0.85938 0.07813 0.23438 1" mesh="L_forearm" />
                                                <geom size="0.04 0.05" pos="0 0.05 0" quat="0.707107 0.707107 0 0" type="cylinder" class="cls" />
                                                <geom size="0.025 0.04" pos="0 0.1451 0" quat="0.707107 0 0.707107 0" type="cylinder" class="cls" />
                                                <body name="L_Wrist1_Link" pos="0 0.1451 0">
                                                    <inertial pos="-0.00158 0.02153 3e-05" quat="0.474698 0.521107 -0.476676 0.525252" mass="0.70923" diaginertia="0.00068319 0.000650504 0.000394066" />
                                                    <joint name="L_Wrist1_Joint" pos="0 0 0" axis="1 0 0" limited="true" range="-3.14159 3.14159" />
                                                    <geom class="viz" rgba="0.20313 0.20313 0.20313 1" mesh="L_wrist1" />
                                                    <geom size="0.02 0.03" pos="0 0.046 0" type="cylinder" class="cls" />
                                                    <body name="L_Wrist2_Link" pos="0 0.046 0">
                                                        <inertial pos="0.00063 0.0536 0.00178" quat="0.707107 0.707107 0 0" mass="1" diaginertia="0.00086545 0.000820823 0.000696917" />
                                                        <joint name="L_Wrist2_Joint" pos="0 0 0" axis="0 0 1" limited="true" range="-2.094 2.094" />
                                                        <geom size="0.03 0.035 0.03" pos="0 0.057 0" type="box" class="cls" />
                                                    </body>
                                                </body>
                                            </body>
                                        </body>
                                    </body>
                                </body>
                            </body>
                        </body>
                        <body name="Neck_Link" pos="-0.036 0 0.3795">
                            <inertial pos="0 -0.00363 -0.0023" quat="0.635583 0.664622 -0.284996 0.270349" mass="0.248" diaginertia="5.85426e-05 5.79997e-05 3.64427e-05" />
                            <joint name="Neck_Joint" pos="0 0 0" axis="0 0 1" limited="true" range="-1.54 1.54" />
                            <geom size="0.07 0.0215" pos="0 0 0.05" type="cylinder" class="cls" />
                            <geom class="viz" rgba="0.20313 0.20313 0.20313 1" pos="-0.036 0 0.3795" mesh="neck" />
                            <!--geom class="cls" size="0.08 0.07 0.1" type="box" pos="-0.016 0 0.547"/-->
                            <body name="Head_Link" pos="0 0 0.0275">
                                <inertial pos="-0.0036 0.0031 0.1289" quat="0.686556 0.0929367 0.0744515 0.717259" mass="3.46332" diaginertia="0.0215996 0.0203681 0.0145263" />
                                <joint name="Head_Joint" pos="0 0 0" axis="0 1 0" limited="true" range="-1.54 1.54" />
                                <geom size="0.07 0.0215" pos="0 0 0.05" type="cylinder" class="cls" />
                                <geom class="viz" rgba="0.85938 0.07813 0.23438 1" pos="-0.036 0 0.407" mesh="head" />
                            </body>
                        </body>
                    </body>
                </body>
            </body>
        </body>
    </worldbody>

    <actuator>
        <motor name="R_HipRoll_Motor" joint="R_HipRoll_Joint"/>
        <motor name="R_HipCenter_Motor" joint="R_HipCenter_Joint"/>
        <motor name="R_Thigh_Motor" joint="R_Thigh_Joint"/>
        <motor name="R_Knee_Motor" joint="R_Knee_Joint"/>
        <motor name="R_AnkleCenter_Motor" joint="R_AnkleCenter_Joint"/>
        <motor name="R_AnkleRoll_Motor" joint="R_AnkleRoll_Joint"/>

        <motor name="L_HipRoll_Motor" joint="L_HipRoll_Joint"/>
        <motor name="L_HipCenter_Motor" joint="L_HipCenter_Joint"/>
        <motor name="L_Thigh_Motor" joint="L_Thigh_Joint"/>
        <motor name="L_Knee_Motor" joint="L_Knee_Joint"/>
        <motor name="L_AnkleCenter_Motor" joint="L_AnkleCenter_Joint"/>
        <motor name="L_AnkleRoll_Motor" joint="L_AnkleRoll_Joint"/>

        <motor name="Waist1_Motor" joint="Waist1_Joint"/>
        <motor name="Waist2_Motor" joint="Waist2_Joint"/>
        <motor name="Upperbody_Motor" joint="Upperbody_Joint"/>

        <motor name="Neck_Motor" joint="Neck_Joint"/>
        <motor name="Head_Motor" joint="Head_Joint"/>


        <motor name="R_Shoulder1_Motor" joint="R_Shoulder1_Joint"/>
        <motor name="R_Shoulder2_Motor" joint="R_Shoulder2_Joint"/>
        <motor name="R_Shoulder3_Motor" joint="R_Shoulder3_Joint"/>
        <motor name="R_Armlink_Motor" joint="R_Armlink_Joint"/>
        <motor name="R_Elbow_Motor" joint="R_Elbow_Joint"/>
        <motor name="R_Forearm_Motor" joint="R_Forearm_Joint"/>
        <motor name="R_Wrist1_Motor" joint="R_Wrist1_Joint"/>
        <motor name="R_Wrist2_Motor" joint="R_Wrist2_Joint"/>

        <motor name="L_Shoulder1_Motor" joint="L_Shoulder1_Joint"/>
        <motor name="L_Shoulder2_Motor" joint="L_Shoulder2_Joint"/>
        <motor name="L_Shoulder3_Motor" joint="L_Shoulder3_Joint"/>
        <motor name="L_Armlink_Motor" joint="L_Armlink_Joint"/>
        <motor name="L_Elbow_Motor" joint="L_Elbow_Joint"/>
        <motor name="L_Forearm_Motor" joint="L_Forearm_Joint"/>
        <motor name="L_Wrist1_Motor" joint="L_Wrist1_Joint"/>
        <motor name="L_Wrist2_Motor" joint="L_Wrist2_Joint"/>
    </actuator>


    <keyframe>
        <!--Initial Position Setting -->
        <key name="front" time="0" qpos ="0 0 0.92683 1 0 0 0 
								0 0 -0.24 0.6 -0.36 0 
								0 0 -0.24 0.6 -0.36 0 
								0 0 0 
                                0 0
								-0.3 -0.3 -1.5 1.27 1 0 1 0 
								0.3 0.3 1.5 -1.27 -1 0 -1 0"/>
    </keyframe>

</mujoco>